<?xml version="1.0" ?>
<!-- =================================================================================== -->
<!-- |    This document was autogenerated by xacro from urdf\angle_excurate_arm_ver2.xacro | -->
<!-- |    EDITING THIS FILE BY HAND IS NOT RECOMMENDED                                 | -->
<!-- =================================================================================== -->
<robot xmlns:xacro="http://www.ros.org/wiki/xacro" name="angle_excurate_arm_ver2">
  <material name="silver">
    <color rgba="0.700 0.700 0.700 1.000"/>
  </material>
  <transmission name="Revolute 1_tran">
    <type>transmission_interface/SimpleTransmission</type>
    <joint name="Revolute 1">
      <hardwareInterface>hardware_interface/EffortJointInterface</hardwareInterface>
    </joint>
    <actuator name="Revolute 1_actr">
      <hardwareInterface>hardware_interface/EffortJointInterface</hardwareInterface>
      <mechanicalReduction>1</mechanicalReduction>
    </actuator>
  </transmission>
  <transmission name="Revolute 2_tran">
    <type>transmission_interface/SimpleTransmission</type>
    <joint name="Revolute 2">
      <hardwareInterface>hardware_interface/EffortJointInterface</hardwareInterface>
    </joint>
    <actuator name="Revolute 2_actr">
      <hardwareInterface>hardware_interface/EffortJointInterface</hardwareInterface>
      <mechanicalReduction>1</mechanicalReduction>
    </actuator>
  </transmission>
  <transmission name="Revolute 3_tran">
    <type>transmission_interface/SimpleTransmission</type>
    <joint name="Revolute 3">
      <hardwareInterface>hardware_interface/EffortJointInterface</hardwareInterface>
    </joint>
    <actuator name="Revolute 3_actr">
      <hardwareInterface>hardware_interface/EffortJointInterface</hardwareInterface>
      <mechanicalReduction>1</mechanicalReduction>
    </actuator>
  </transmission>
  <transmission name="Revolute 4_tran">
    <type>transmission_interface/SimpleTransmission</type>
    <joint name="Revolute 4">
      <hardwareInterface>hardware_interface/EffortJointInterface</hardwareInterface>
    </joint>
    <actuator name="Revolute 4_actr">
      <hardwareInterface>hardware_interface/EffortJointInterface</hardwareInterface>
      <mechanicalReduction>1</mechanicalReduction>
    </actuator>
  </transmission>
  <transmission name="Revolute 5_tran">
    <type>transmission_interface/SimpleTransmission</type>
    <joint name="Revolute 5">
      <hardwareInterface>hardware_interface/EffortJointInterface</hardwareInterface>
    </joint>
    <actuator name="Revolute 5_actr">
      <hardwareInterface>hardware_interface/EffortJointInterface</hardwareInterface>
      <mechanicalReduction>1</mechanicalReduction>
    </actuator>
  </transmission>
  <transmission name="Revolute 6_tran">
    <type>transmission_interface/SimpleTransmission</type>
    <joint name="Revolute 6">
      <hardwareInterface>hardware_interface/EffortJointInterface</hardwareInterface>
    </joint>
    <actuator name="Revolute 6_actr">
      <hardwareInterface>hardware_interface/EffortJointInterface</hardwareInterface>
      <mechanicalReduction>1</mechanicalReduction>
    </actuator>
  </transmission>
  <gazebo>
    <plugin name="control" filename="libgazebo_ros_control.so"/>
  </gazebo>
  <gazebo reference="base_link">
    <material>Gazebo/Silver</material>
    <mu1>0.2</mu1>
    <mu2>0.2</mu2>
    <selfCollide>true</selfCollide>
    <gravity>true</gravity>
  </gazebo>
  <gazebo reference="base_link2_v2_1">
    <material>Gazebo/Silver</material>
    <mu1>0.2</mu1>
    <mu2>0.2</mu2>
    <selfCollide>true</selfCollide>
  </gazebo>
  <gazebo reference="link3_v1_1">
    <material>Gazebo/Silver</material>
    <mu1>0.2</mu1>
    <mu2>0.2</mu2>
    <selfCollide>true</selfCollide>
  </gazebo>
  <gazebo reference="link4_v1_1">
    <material>Gazebo/Silver</material>
    <mu1>0.2</mu1>
    <mu2>0.2</mu2>
    <selfCollide>true</selfCollide>
  </gazebo>
  <gazebo reference="robot_ver7_link_4_v1_1">
    <material>Gazebo/Silver</material>
    <mu1>0.2</mu1>
    <mu2>0.2</mu2>
    <selfCollide>true</selfCollide>
  </gazebo>
  <gazebo reference="robot_ver7_grap2_2_v1_1">
    <material>Gazebo/Silver</material>
    <mu1>0.2</mu1>
    <mu2>0.2</mu2>
    <selfCollide>true</selfCollide>
  </gazebo>
  <gazebo reference="robot_ver7_grap1_2_v1_1">
    <material>Gazebo/Silver</material>
    <mu1>0.2</mu1>
    <mu2>0.2</mu2>
    <selfCollide>true</selfCollide>
  </gazebo>
  <gazebo reference="base_link_2_1">
    <material>Gazebo/Silver</material>
    <mu1>0.2</mu1>
    <mu2>0.2</mu2>
    <selfCollide>true</selfCollide>
  </gazebo>
  <link name="base_link">
    <inertial>
      <origin xyz="1.8745796736605483e-12 -2.6846557552026664e-18 0.04000014999999999" rpy="0 0 0"/>
      <mass value="7.925585093654501e-07"/>
      <inertia ixx="0.0" iyy="0.0" izz="0.0" ixy="-0.0" iyz="-0.0" ixz="-0.0"/>
    </inertial>
    <visual>
      <origin xyz="0 0 0" rpy="0 0 0"/>
      <geometry>
        <mesh filename="package://robot_description/meshes/base_link.stl" scale="0.001 0.001 0.001"/>
      </geometry>
      <material name="silver"/>
    </visual>
    <collision>
      <origin xyz="0 0 0" rpy="0 0 0"/>
      <geometry>
        <mesh filename="package://robot_description/meshes/base_link.stl" scale="0.001 0.001 0.001"/>
      </geometry>
    </collision>
  </link>
  <link name="base_link2_v2_1">
    <inertial>
      <origin xyz="-5.553953613832533e-14 1.6607364926774611e-07 0.04484512943360931" rpy="0 0 0"/>
      <mass value="0.8724221516717809"/>
      <inertia ixx="0.000636" iyy="0.000529" izz="0.000308" ixy="0.0" iyz="0.0" ixz="0.0"/>
    </inertial>
    <visual>
      <origin xyz="0.0 -0.0 -0.076" rpy="0 0 0"/>
      <geometry>
        <mesh filename="package://robot_description/meshes/base_link2_v2_1.stl" scale="0.001 0.001 0.001"/>
      </geometry>
      <material name="silver"/>
    </visual>
    <collision>
      <origin xyz="0.0 -0.0 -0.076" rpy="0 0 0"/>
      <geometry>
        <mesh filename="package://robot_description/meshes/base_link2_v2_1.stl" scale="0.001 0.001 0.001"/>
      </geometry>
    </collision>
  </link>
  <link name="link3_v1_1">
    <inertial>
      <origin xyz="0.08484392825641267 8.013781706481686e-08 0.10111325630955267" rpy="0 0 0"/>
      <mass value="1.7894494256516058"/>
      <inertia ixx="0.00475" iyy="0.007559" izz="0.003484" ixy="-0.0" iyz="-0.0" ixz="-0.003589"/>
    </inertial>
    <visual>
      <origin xyz="0.0 0.0 -0.146342" rpy="0 0 0"/>
      <geometry>
        <mesh filename="package://robot_description/meshes/link3_v1_1.stl" scale="0.001 0.001 0.001"/>
      </geometry>
      <material name="silver"/>
    </visual>
    <collision>
      <origin xyz="0.0 0.0 -0.146342" rpy="0 0 0"/>
      <geometry>
        <mesh filename="package://robot_description/meshes/link3_v1_1.stl" scale="0.001 0.001 0.001"/>
      </geometry>
    </collision>
  </link>
  <link name="link4_v1_1">
    <inertial>
      <origin xyz="0.14822703980623636 -1.61812620875914e-09 0.017829758669321516" rpy="0 0 0"/>
      <mass value="2.301167222256875"/>
      <inertia ixx="0.001028" iyy="0.010731" izz="0.010331" ixy="0.0" iyz="0.0" ixz="-0.000548"/>
    </inertial>
    <visual>
      <origin xyz="-0.137776 0.0 -0.310538" rpy="0 0 0"/>
      <geometry>
        <mesh filename="package://robot_description/meshes/link4_v1_1.stl" scale="0.001 0.001 0.001"/>
      </geometry>
      <material name="silver"/>
    </visual>
    <collision>
      <origin xyz="-0.137776 0.0 -0.310538" rpy="0 0 0"/>
      <geometry>
        <mesh filename="package://robot_description/meshes/link4_v1_1.stl" scale="0.001 0.001 0.001"/>
      </geometry>
    </collision>
  </link>
  <link name="robot_ver7_link_4_v1_1">
    <inertial>
      <origin xyz="0.017892495703134614 -1.618123421275575e-09 0.00315495193392884" rpy="0 0 0"/>
      <mass value="0.1836674229836172"/>
      <inertia ixx="9.9e-05" iyy="0.000103" izz="7.2e-05" ixy="0.0" iyz="0.0" ixz="5e-06"/>
    </inertial>
    <visual>
      <origin xyz="-0.36806 0.0 -0.352664" rpy="0 0 0"/>
      <geometry>
        <mesh filename="package://robot_description/meshes/robot_ver7_link_4_v1_1.stl" scale="0.001 0.001 0.001"/>
      </geometry>
      <material name="silver"/>
    </visual>
    <collision>
      <origin xyz="-0.36806 0.0 -0.352664" rpy="0 0 0"/>
      <geometry>
        <mesh filename="package://robot_description/meshes/robot_ver7_link_4_v1_1.stl" scale="0.001 0.001 0.001"/>
      </geometry>
    </collision>
  </link>
  <link name="robot_ver7_grap2_2_v1_1">
    <inertial>
      <origin xyz="0.03188464924792617 -0.0055870722111964685 0.00827502813362846" rpy="0 0 0"/>
      <mass value="0.04062678364092949"/>
      <inertia ixx="4e-06" iyy="2.6e-05" izz="2.5e-05" ixy="-0.0" iyz="-0.0" ixz="-6e-06"/>
    </inertial>
    <visual>
      <origin xyz="-0.409619 0.0125 -0.359992" rpy="0 0 0"/>
      <geometry>
        <mesh filename="package://robot_description/meshes/robot_ver7_grap2_2_v1_1.stl" scale="0.001 0.001 0.001"/>
      </geometry>
      <material name="silver"/>
    </visual>
    <collision>
      <origin xyz="-0.409619 0.0125 -0.359992" rpy="0 0 0"/>
      <geometry>
        <mesh filename="package://robot_description/meshes/robot_ver7_grap2_2_v1_1.stl" scale="0.001 0.001 0.001"/>
      </geometry>
    </collision>
  </link>
  <link name="robot_ver7_grap1_2_v1_1">
    <inertial>
      <origin xyz="0.03188464924792689 0.005587068974950284 0.008275028133628792" rpy="0 0 0"/>
      <mass value="0.040626783640931655"/>
      <inertia ixx="4e-06" iyy="2.6e-05" izz="2.5e-05" ixy="0.0" iyz="0.0" ixz="-6e-06"/>
    </inertial>
    <visual>
      <origin xyz="-0.409619 -0.0125 -0.359992" rpy="0 0 0"/>
      <geometry>
        <mesh filename="package://robot_description/meshes/robot_ver7_grap1_2_v1_1.stl" scale="0.001 0.001 0.001"/>
      </geometry>
      <material name="silver"/>
    </visual>
    <collision>
      <origin xyz="-0.409619 -0.0125 -0.359992" rpy="0 0 0"/>
      <geometry>
        <mesh filename="package://robot_description/meshes/robot_ver7_grap1_2_v1_1.stl" scale="0.001 0.001 0.001"/>
      </geometry>
    </collision>
  </link>
  <link name="base_link_2_1">
    <inertial>
      <origin xyz="-7.6976007193707615e-16 1.23599521765243e-16 -0.010056885130538304" rpy="0 0 0"/>
      <mass value="1.6067306789990348"/>
      <inertia ixx="0.003521" iyy="0.006468" izz="0.008802" ixy="0.0" iyz="-0.0" ixz="0.0"/>
    </inertial>
    <visual>
      <origin xyz="-0.0 -0.0 -0.04" rpy="0 0 0"/>
      <geometry>
        <mesh filename="package://robot_description/meshes/base_link_2_1.stl" scale="0.001 0.001 0.001"/>
      </geometry>
      <material name="silver"/>
    </visual>
    <collision>
      <origin xyz="-0.0 -0.0 -0.04" rpy="0 0 0"/>
      <geometry>
        <mesh filename="package://robot_description/meshes/base_link_2_1.stl" scale="0.001 0.001 0.001"/>
      </geometry>
    </collision>
  </link>
  <joint name="Revolute 1" type="revolute">
    <origin xyz="-0.0 0.0 0.036" rpy="0 0 0"/>
    <parent link="base_link_2_1"/>
    <child link="base_link2_v2_1"/>
    <axis xyz="0.0 -0.0 1.0"/>
    <limit upper="3.141593" lower="0.0" effort="100" velocity="100"/>
  </joint>
  <joint name="Revolute 2" type="revolute">
    <origin xyz="0.0 -0.0 0.070342" rpy="0 0 0"/>
    <parent link="base_link2_v2_1"/>
    <child link="link3_v1_1"/>
    <axis xyz="-0.0 -1.0 0.0"/>
    <limit upper="2.094395" lower="0.0" effort="100" velocity="100"/>
  </joint>
  <joint name="Revolute 3" type="revolute">
    <origin xyz="0.137776 0.0 0.164196" rpy="0 0 0"/>
    <parent link="link3_v1_1"/>
    <child link="link4_v1_1"/>
    <axis xyz="-0.0 -1.0 0.0"/>
    <limit upper="2.617994" lower="0.0" effort="100" velocity="100"/>
  </joint>
  <joint name="Revolute 4" type="revolute">
    <origin xyz="0.230284 0.0 0.042126" rpy="0 0 0"/>
    <parent link="link4_v1_1"/>
    <child link="robot_ver7_link_4_v1_1"/>
    <axis xyz="0.984808 0.0 0.173648"/>
    <limit upper="3.141593" lower="0.0" effort="100" velocity="100"/>
  </joint>
  <joint name="Revolute 5" type="revolute">
    <origin xyz="0.041559 -0.0125 0.007328" rpy="0 0 0"/>
    <parent link="robot_ver7_link_4_v1_1"/>
    <child link="robot_ver7_grap2_2_v1_1"/>
    <axis xyz="0.173648 -0.0 -0.984808"/>
    <limit upper="1.22173" lower="0.0" effort="100" velocity="100"/>
  </joint>
  <joint name="Revolute 6" type="revolute">
    <origin xyz="0.041559 0.0125 0.007328" rpy="0 0 0"/>
    <parent link="robot_ver7_link_4_v1_1"/>
    <child link="robot_ver7_grap1_2_v1_1"/>
    <axis xyz="-0.173648 0.0 0.984808"/>
    <limit upper="1.22173" lower="0.0" effort="100" velocity="100"/>
  </joint>
  <joint name="Rigid 8" type="fixed">
    <origin xyz="0.0 0.0 0.04" rpy="0 0 0"/>
    <parent link="base_link"/>
    <child link="base_link_2_1"/>
  </joint>
</robot>
